ply
format ascii 1.0
comment : MagicaVoxel @ Ephtracy
element vertex 86
property float x
property float y
property float z
property uchar red
property uchar green
property uchar blue
end_header
-4 -4 0 102 153 255
-3 -4 0 102 153 255
-2 -4 0 102 153 255
-1 -4 0 102 153 255
0 -4 0 102 153 255
1 -4 0 102 153 255
2 -4 0 102 153 255
3 -4 0 102 153 255
-4 -3 0 102 153 255
3 -3 0 102 153 255
-4 -2 0 102 153 255
3 -2 0 102 153 255
-4 -1 0 102 153 255
3 -1 0 102 153 255
-4 0 0 102 153 255
-3 0 0 187 187 187
-2 0 0 187 187 187
-1 0 0 187 187 187
0 0 0 187 187 187
1 0 0 187 187 187
2 0 0 187 187 187
3 0 0 102 153 255
-4 1 0 102 153 255
-1 1 0 187 187 187
0 1 0 187 187 187
3 1 0 102 153 255
-4 2 0 102 153 255
-1 2 0 187 187 187
0 2 0 187 187 187
3 2 0 102 153 255
-4 3 0 102 153 255
-3 3 0 102 153 255
-2 3 0 102 153 255
-1 3 0 102 153 255
0 3 0 102 153 255
1 3 0 102 153 255
2 3 0 102 153 255
3 3 0 102 153 255
-1 -4 1 102 51 204
0 -4 1 102 51 204
-1 -3 1 102 51 204
0 -3 1 102 51 204
-4 -1 1 187 187 187
3 -1 1 187 187 187
-4 0 1 187 187 187
3 0 1 187 187 187
-1 3 1 187 187 187
0 3 1 187 187 187
-1 -3 2 102 51 204
0 -3 2 102 51 204
-1 -2 2 102 51 204
0 -2 2 102 51 204
-3 -1 2 187 187 187
-1 -1 2 102 51 204
0 -1 2 102 51 204
2 -1 2 187 187 187
-3 0 2 187 187 187
-1 0 2 102 51 204
0 0 2 102 51 204
2 0 2 187 187 187
-1 1 2 102 51 204
0 1 2 102 51 204
-1 2 2 102 51 204
0 2 2 102 51 204
-1 3 2 187 187 187
0 3 2 187 187 187
-2 -1 3 187 187 187
1 -1 3 187 187 187
-2 0 3 187 187 187
1 0 3 187 187 187
-1 2 3 187 187 187
0 2 3 187 187 187
-1 3 3 187 187 187
0 3 3 187 187 187
-1 -1 4 187 187 187
0 -1 4 187 187 187
-1 0 4 187 187 187
0 0 4 187 187 187
-1 1 4 187 187 187
0 1 4 187 187 187
-1 2 4 187 187 187
0 2 4 187 187 187
-1 -1 5 187 187 187
0 -1 5 187 187 187
-1 0 5 187 187 187
0 0 5 187 187 187
